<?xml version="1.0" ?>
<!-- =================================================================================== -->
<!-- |    This document was autogenerated by xacro from panda.xacro                    | -->
<!-- |    EDITING THIS FILE BY HAND IS NOT RECOMMENDED                                 | -->
<!-- =================================================================================== -->
<robot name="panda">
  <!--! TEST -->
  <!-- <xacro:include filename="../joints.xacro"/>
    <xacro:include filename="../materials.xacro"/>
    <xacro:include filename="../constants.xacro"/> 
    <xacro:body/> -->
  <!--!TEST -->
  <!-- <xacro:include filename="joints.xacro" /> 
    <xacro:include filename="constants.xacro" />
    <xacro:include filename="materials.xacro" />
    <link name="base" />
    <xacro:panda_arm_L1 prefix="RF" parent="base" xyz="0 0 0" rpy="0 0 0" /> -->
  <!--!TEST -->
  <!-- <xacro:include filename="joints.xacro" />
    <xacro:include filename="constants.xacro" />
    <xacro:include filename="materials.xacro" />
    <link name="base" />
    <xacro:panda_arm_L2 prefix="RF" parent="base" xyz="0 0 0" rpy="0 0 0" /> -->
  <!--!TEST -->
  <!-- <xacro:include filename="joints.xacro" />  
    <xacro:include filename="constants.xacro" />
    <xacro:include filename="materials.xacro" />
    <link name="base" />
    <xacro:panda_arm_L3 prefix="RF" parent="base" xyz="0 0 0" rpy="0 0 0" /> -->
  <!--!TEST -->
  <!-- <xacro:include filename="joints.xacro" />  
    <xacro:include filename="constants.xacro" />
    <xacro:include filename="materials.xacro" />
    <link name="base" />
    <xacro:panda_arm_L4 prefix="RF" parent="base" xyz="0 0 0" rpy="0 0 0" /> -->
  <!--!TEST -->
  <!-- <xacro:include filename="joints.xacro" />  
    <xacro:include filename="constants.xacro" />
    <xacro:include filename="materials.xacro" />
    <link name="base" />
    <xacro:panda_arm_L5 prefix="RF" parent="base" xyz="0 0 0" rpy="0 0 0" /> -->
  <!--!TEST -->
  <!-- <xacro:include filename="../joints.xacro" />  
    <xacro:include filename="../constants.xacro" />
    <xacro:include filename="../materials.xacro" />
    <link name="base" />
    <xacro:panda_arm_L6 prefix="RF" parent="base" xyz="0 0 0" rpy="0 0 0" /> -->
  <!--!TEST -->
  <!-- <xacro:include filename="joints.xacro" />  
    <xacro:include filename="constants.xacro" />
    <xacro:include filename="materials.xacro" />

    <link name="base" />
    <xacro:panda_arm_L7 prefix="RF" parent="base" xyz="0 0 0" rpy="0 0 0" /> -->
  <!--! TEST -->
  <!-- <xacro:include filename="../joints.xacro"/>
    <xacro:include filename="../materials.xacro"/>
    <xacro:include filename="../constants.xacro"/>
    <link name="base"/>
    <xacro:lf_arm prefix="LF" parent="base" xyz="0 0 0" rpy="0 0 ${pi}"/> -->
  <!--!TEST -->
  <!-- <xacro:include filename="joints.xacro" /> 
    <xacro:include filename="constants.xacro" />
    <xacro:include filename="materials.xacro" />
    <link name="base" />
    <xacro:panda_arm_L1 prefix="RF" parent="base" xyz="0 0 0" rpy="0 0 0" /> -->
  <!--!TEST -->
  <!-- <xacro:include filename="joints.xacro" />
    <xacro:include filename="constants.xacro" />
    <xacro:include filename="materials.xacro" />
    <link name="base" />
    <xacro:panda_arm_L2 prefix="RF" parent="base" xyz="0 0 0" rpy="0 0 0" /> -->
  <!--!TEST -->
  <!-- <xacro:include filename="joints.xacro" />  
    <xacro:include filename="constants.xacro" />
    <xacro:include filename="materials.xacro" />
    <link name="base" />
    <xacro:panda_arm_L3 prefix="RF" parent="base" xyz="0 0 0" rpy="0 0 0" /> -->
  <!--!TEST -->
  <!-- <xacro:include filename="joints.xacro" />  
    <xacro:include filename="constants.xacro" />
    <xacro:include filename="materials.xacro" />
    <link name="base" />
    <xacro:panda_arm_L4 prefix="RF" parent="base" xyz="0 0 0" rpy="0 0 0" /> -->
  <!--!TEST -->
  <!-- <xacro:include filename="joints.xacro" />  
    <xacro:include filename="constants.xacro" />
    <xacro:include filename="materials.xacro" />
    <link name="base" />
    <xacro:panda_arm_L5 prefix="RF" parent="base" xyz="0 0 0" rpy="0 0 0" /> -->
  <!--!TEST -->
  <!-- <xacro:include filename="../joints.xacro" />  
    <xacro:include filename="../constants.xacro" />
    <xacro:include filename="../materials.xacro" />
    <link name="base" />
    <xacro:panda_arm_L6 prefix="RF" parent="base" xyz="0 0 0" rpy="0 0 0" /> -->
  <!--!TEST -->
  <!-- <xacro:include filename="joints.xacro" />  
    <xacro:include filename="constants.xacro" />
    <xacro:include filename="materials.xacro" />

    <link name="base" />
    <xacro:panda_arm_L7 prefix="RF" parent="base" xyz="0 0 0" rpy="0 0 0" /> -->
  <!--! TEST -->
  <!-- <xacro:include filename="../joints.xacro"/>
    <xacro:include filename="../materials.xacro"/>
    <xacro:include filename="../constants.xacro"/>
    <link name="base"/>
    <xacro:rf_arm prefix="RF" parent="base" xyz="0 0 0" rpy="0 0 0"/> -->
  <!--!TEST -->
  <!-- <xacro:include filename="../joints.xacro" /> 
    <xacro:include filename="../constants.xacro" />
    <xacro:include filename="../materials.xacro" />
    <link name="base" />
    <xacro:panda_leg_L1 prefix="RF" parent="base" xyz="0 0 0" rpy="0 0 0" /> -->
  <!--!TEST -->
  <!-- <xacro:include filename="../joints.xacro" /> 
    <xacro:include filename="../constants.xacro" />
    <xacro:include filename="../materials.xacro" />
    <link name="base" />
    <xacro:panda_leg_L2_lb prefix="RF" parent="base" xyz="0 0 0" rpy="0 0 0" /> -->
  <!--!TEST -->
  <!-- <xacro:include filename="../joints.xacro" /> 
    <xacro:include filename="../constants.xacro" />
    <xacro:include filename="../materials.xacro" />
    <link name="base" />
    <xacro:panda_leg_L3 prefix="RF" parent="base" xyz="0 0 0" rpy="0 0 0" /> -->
  <!--!TEST -->
  <!-- <xacro:include filename="../joints.xacro" /> 
    <xacro:include filename="../constants.xacro" />
    <xacro:include filename="../materials.xacro" />
    <link name="base" />
    <xacro:panda_leg_L4 prefix="RF" parent="base" xyz="0 0 0" rpy="0 0 0"/> -->
  <!--!TEST -->
  <!-- <xacro:include filename="../joints.xacro" />  
    <xacro:include filename="../constants.xacro" />
    <xacro:include filename="../materials.xacro" />

    <link name="base" />
    <xacro:panda_leg_L5 prefix="RF" parent="base" xyz="0 0 0" rpy="0 0 0" /> -->
  <!--! TEST -->
  <!-- <xacro:include filename="../joints.xacro"/>
    <xacro:include filename="../materials.xacro"/>
    <xacro:include filename="../constants.xacro"/>
    <link name="base"/>
    <xacro:lb_leg prefix="LB" parent="base" xyz="0 0 0" rpy="${pi/2} 0 0"/> -->
  <!--!TEST -->
  <!-- <xacro:include filename="../joints.xacro" /> 
    <xacro:include filename="../constants.xacro" />
    <xacro:include filename="../materials.xacro" />
    <link name="base" />
    <xacro:panda_leg_L1 prefix="RF" parent="base" xyz="0 0 0" rpy="0 0 0" /> -->
  <!--!TEST -->
  <!-- <xacro:include filename="../joints.xacro" /> 
    <xacro:include filename="../constants.xacro" />
    <xacro:include filename="../materials.xacro" />
    <link name="base" />
    <xacro:panda_leg_L2_rb prefix="RF" parent="base" xyz="0 0 0" rpy="0 0 0" /> -->
  <!--!TEST -->
  <!-- <xacro:include filename="../joints.xacro" /> 
    <xacro:include filename="../constants.xacro" />
    <xacro:include filename="../materials.xacro" />
    <link name="base" />
    <xacro:panda_leg_L3 prefix="RF" parent="base" xyz="0 0 0" rpy="0 0 0" /> -->
  <!--!TEST -->
  <!-- <xacro:include filename="../joints.xacro" /> 
    <xacro:include filename="../constants.xacro" />
    <xacro:include filename="../materials.xacro" />
    <link name="base" />
    <xacro:panda_leg_L4 prefix="RF" parent="base" xyz="0 0 0" rpy="0 0 0"/> -->
  <!--!TEST -->
  <!-- <xacro:include filename="../joints.xacro" />  
    <xacro:include filename="../constants.xacro" />
    <xacro:include filename="../materials.xacro" />

    <link name="base" />
    <xacro:panda_leg_L5 prefix="RF" parent="base" xyz="0 0 0" rpy="0 0 0" /> -->
  <!--! TEST -->
  <!-- <xacro:include filename="../joints.xacro"/>
    <xacro:include filename="../materials.xacro"/>
    <xacro:include filename="../constants.xacro"/>
    <link name="base"/>
    <xacro:rb_leg prefix="RB" parent="base" xyz="0 0 0" rpy="${-pi/2} 0 0"/> -->
  <!-- <xacro:macro name="panda_body">
        <link name="body">
            <visual>
                <origin xyz="0 0 0" rpy="0 0 0" />
                <geometry>
                    <box size="0.2 0.4 0.025"/>
                </geometry>
                <material name="grey" />
            </visual>
            <collision>
                <origin xyz="0 0 0" rpy="0 0 0" />
                <geometry>
                    <box size="0.2 0.4 0.025"/>

                </geometry>
            </collision>
        </link>
    </xacro:macro> -->
  <!-- <xacro:property name="mesh_path" value="package://robot_description/meshes/panda_arm"/> -->
  <material name="red">
    <color rgba="1 0 0 1"/>
  </material>
  <material name="grey">
    <color rgba="0.75 0.75 0.75 1"/>
  </material>
  <material name="green">
    <color rgba="0 1 0 1"/>
  </material>
  <material name="blue">
    <color rgba="0 0 1 1"/>
  </material>
  <!-- <xacro:property name="body_mesh_path" value="/home/q200/workspace/src/robot_description/meshes/panda_body"/>
    <xacro:property name="arm_mesh_path" value="/home/q200/workspace/src/robot_description/meshes/panda_arm"/>
    <xacro:property name="leg_mesh_path" value="/home/q200/workspace/src/robot_description/meshes/panda_leg"/> -->
  <!-- World anchor: fixes the chassis in place for display/simulation -->
  <!-- <link name="world"/>
  <joint name="world_to_body" type="fixed">
    <parent link="world"/>
    <child link="body"/>
    <origin rpy="0 0 0" xyz="0 0 0.5"/>
  </joint> -->

  <link name="body">
    <visual>
      <origin rpy="0 0 0" xyz="0 0 0"/>
      <geometry>
        <mesh filename="package://robot_description/meshes/panda_body//body.dae" scale="1 1 1"/>
      </geometry>
      <material name="red"/>
    </visual>
    <collision>
      <origin rpy="0 1.5707963267948966 0" xyz="0.02 0 -0.025"/>
      <geometry>
        <cylinder length="0.04" radius="0.06"/>
      </geometry>
    </collision>
    <collision>
      <origin rpy="0 1.5707963267948966 0" xyz="0.115 0 -0.07"/>
      <geometry>
        <cylinder length="0.14" radius="0.075"/>
      </geometry>
    </collision>
    <collision>
      <origin rpy="0 1.5707963267948966 0" xyz="0.25 0 -0.0025"/>
      <geometry>
        <cylinder length="0.125" radius="0.045"/>
      </geometry>
    </collision>
    <!-- INERTIA body  -->
    <inertial>
      <origin rpy="0 0 0" xyz="0.111021 0.001066 -0.054499"/>
      <mass value="0.6"/>
      <inertia ixx="0.00341830" ixy="-0.00001942" ixz="-0.00061387" iyy="0.00715863" iyz="-0.00000747" izz="0.00795982"/>
    </inertial>
   
  </link>
  <joint name="RF_J1" type="revolute">
    <parent link="body"/>
    <child link="RF_L1"/>
    <origin rpy="0 0 -1.5707963267948966" xyz="0.28 -0.075 0.005"/>
    <axis xyz="1 0 0"/>
    <limit effort="10.0" lower="-1.5707963267948966" upper="1.5707963267948966" velocity="10.0"/>
    <dynamics damping="0.1" friction="0.0"/>
  </joint>
  <link name="RF_L1">
    <visual>
      <origin rpy="0 0 0" xyz="0 0 0"/>
      <geometry>
        <mesh filename="package://robot_description/meshes/panda_arm/Link1.dae" scale="1 1 1"/>
      </geometry>
      <material name="red"/>
    </visual>
    <collision>
      <origin rpy="0 0 0" xyz="0.025 0.0 -0.01"/>
      <geometry>
        <cylinder length="0.085" radius="0.025"/>
      </geometry>
    </collision>
    <!-- INERTIA RF_L1  -->
    <inertial>
      <origin rpy="0 0 0" xyz="0.024340 0.000290 -0.009336"/>
      <mass value="0.21205"/>
      <inertia ixx="0.00014885" ixy="-0.00000038" ixz="0.00000863" iyy="0.00012057" iyz="0.00000411" izz="0.00009025"/>
    </inertial>
   
  </link>
  <joint name="RF_J2" type="revolute">
    <parent link="RF_L1"/>
    <child link="RF_L2"/>
    <origin rpy="0 0 -1.5707963267948966" xyz="0.026 0.0025 -0.0375"/>
    <axis xyz="1 0 0"/>
    <limit effort="10.0" lower="-1.5707963267948966" upper="1.5707963267948966" velocity="10.0"/>
    <dynamics damping="0.1" friction="0.0"/>
  </joint>
  <link name="RF_L2">
    <visual>
      <origin rpy="0 0 0" xyz="0 0 0"/>
      <geometry>
        <mesh filename="package://robot_description/meshes/panda_arm/Link2.dae" scale="1 1 1"/>
      </geometry>
      <material name="red"/>
    </visual>
    <collision>
      <origin rpy="0 0 0" xyz="0.0 0.01 -0.055"/>
      <geometry>
        <cylinder length="0.04" radius="0.025"/>
      </geometry>
    </collision>
    <!-- INERTIA RF_L2  -->
    <inertial>
      <origin rpy="0 0 0" xyz="0.000319 0.007895 -0.042269"/>
      <mass value="0.12339"/>
      <inertia ixx="0.00007467" ixy="0.00000015" ixz="-0.00000018" iyy="0.00007863" iyz="0.00000833" izz="0.00005700"/>
    </inertial>
   
  </link>
  <joint name="RF_J3" type="revolute">
    <parent link="RF_L2"/>
    <child link="RF_L3"/>
    <origin rpy="0 1.5707963267948966 3.141592653589793" xyz="0 -0.004 -0.0555"/>
    <axis xyz="1 0 0"/>
    <limit effort="10.0" lower="-1.5707963267948966" upper="1.5707963267948966" velocity="10.0"/>
    <dynamics damping="0.1" friction="0.0"/>
  </joint>
  <link name="RF_L3">
    <visual>
      <origin rpy="0 0 0" xyz="0 0 0"/>
      <geometry>
        <mesh filename="package://robot_description/meshes/panda_arm/Link3.dae" scale="1 1 1"/>
      </geometry>
      <material name="red"/>
    </visual>
    <collision>
      <origin rpy="1.5707963267948966 0 0" xyz="0.005 0.028 0.0"/>
      <geometry>
        <cylinder length="0.01" radius="0.025"/>
      </geometry>
    </collision>
    <!-- INERTIA RF_L3  -->
    <inertial>
      <origin rpy="0 0 0" xyz="0.017019 0.023760 -0.000188"/>
      <mass value="0.02605"/>
      <inertia ixx="0.00000523" ixy="0.00000090" ixz="0.00000009" iyy="0.00013027" iyz="0.00000007" izz="0.00001104"/>
    </inertial>
   
  </link>
  <joint name="RF_J4" type="revolute">
    <parent link="RF_L3"/>
    <child link="RF_L4"/>
    <origin rpy="0 -1.5707963267948966 0" xyz="0.058 0.0195 0.001"/>
    <axis xyz="1 0 0"/>
    <limit effort="10.0" lower="-1.5707963267948966" upper="1.5707963267948966" velocity="10.0"/>
    <dynamics damping="0.1" friction="0.0"/>
  </joint>
  <link name="RF_L4">
    <visual>
      <origin rpy="0 0 0" xyz="0 0 0"/>
      <geometry>
        <mesh filename="package://robot_description/meshes/panda_arm/Link4.dae" scale="1 1 1"/>
      </geometry>
      <material name="red"/>
    </visual>
    <collision>
      <origin rpy="0 0 0" xyz="0.01 -0.015 -0.04"/>
      <geometry>
        <cylinder length="0.05" radius="0.03"/>
      </geometry>
    </collision>
    <!-- INERTIA RF_L4  -->
    <inertial>
      <origin rpy="0 0 0" xyz="0.005528 -0.015452 -0.024028"/>
      <mass value="0.21197"/>
      <inertia ixx="0.00016760" ixy="-0.00000028" ixz="0.00001932" iyy="0.00017551" iyz="-0.00000051" izz="0.00008108"/>
    </inertial>
   
  </link>
  <joint name="RF_J5" type="revolute">
    <parent link="RF_L4"/>
    <child link="RF_L5"/>
    <origin rpy="1.5707963267948966 -1.5707963267948966 0" xyz="-0.0073 -0.016 -0.04725"/>
    <axis xyz="1 0 0"/>
    <limit effort="10.0" lower="-1.5707963267948966" upper="1.5707963267948966" velocity="10.0"/>
    <dynamics damping="0.1" friction="0.0"/>
  </joint>
  <link name="RF_L5">
    <visual>
      <origin rpy="0 0 0" xyz="0 0 0"/>
      <geometry>
        <mesh filename="package://robot_description/meshes/panda_arm/Link5.dae" scale="1 1 1"/>
      </geometry>
      <material name="red"/>
    </visual>
    <collision>
      <origin rpy="1.5707963267948966 0 1.5707963267948966" xyz="-0.05 0.0225 0"/>
      <geometry>
        <cylinder length="0.0525" radius="0.0175"/>
      </geometry>
    </collision>
    <!-- INERTIA RF_L5  -->
    <inertial>
      <origin rpy="0 0 0" xyz="-0.039812 0.022259 -0.000292"/>
      <mass value="0.11428"/>
      <inertia ixx="0.00002245" ixy="-0.00000489" ixz="-0.00000014" iyy="0.00008311" iyz="-0.00000020" izz="0.00007996"/>
    </inertial>
   
  </link>
  <joint name="RF_J6" type="revolute">
    <parent link="RF_L5"/>
    <child link="RF_L6"/>
    <origin rpy="0 1.5707963267948966 0" xyz="-0.065 0.021 0"/>
    <axis xyz="1 0 0"/>
    <limit effort="10.0" lower="-1.5707963267948966" upper="1.5707963267948966" velocity="10.0"/>
    <dynamics damping="0.1" friction="0.0"/>
  </joint>
  <link name="RF_L6">
    <visual>
      <origin rpy="0 0 0" xyz="0 0 0"/>
      <geometry>
        <mesh filename="package://robot_description/meshes/panda_arm/Link6.dae" scale="1 1 1"/>
      </geometry>
      <material name="red"/>
    </visual>
    <collision>
      <origin rpy="0 0 0" xyz="0.0 0.0 -0.06"/>
      <geometry>
        <box size="0.065 0.02 0.06"/>
        <!-- TODO: set x y z size -->
      </geometry>
    </collision>
    <!-- INERTIA RF_L6  -->
    <inertial>
      <origin rpy="0 0 0" xyz="-0.005400 0.000762 -0.054807"/>
      <mass value="0.20986"/>
      <inertia ixx="0.00011473" ixy="-0.00001510" ixz="0.00000999" iyy="0.00017398" iyz="0.00001411" izz="0.00013573"/>
    </inertial>
   
  </link>
  <joint name="RF_J7" type="revolute">
    <parent link="RF_L6"/>
    <child link="RF_L7"/>
    <origin rpy="0 0 0" xyz="0 0.007 -0.08"/>
    <axis xyz="1 0 0"/>
    <limit effort="10.0" lower="-1.5707963267948966" upper="1.5707963267948966" velocity="10.0"/>
    <dynamics damping="0.1" friction="0.0"/>
  </joint>
  <link name="RF_L7">
    <visual>
      <origin rpy="0 0 0" xyz="0 0 0"/>
      <geometry>
        <mesh filename="package://robot_description/meshes/panda_arm/Link7.dae" scale="1 1 1"/>
      </geometry>
      <!-- <material name="blue" /> -->
    </visual>
    <collision>
      <!-- <origin xyz="0 0 0" rpy="0 0 0" />
                <geometry>
                    <mesh filename="${arm_mesh_path}/Link7.dae" scale="1 1 1" />
                </geometry> -->
      <origin rpy="0 0 0" xyz="0.0 0.0 -0.05"/>
      <geometry>
        <!-- <mesh filename="${meshes_path}/Link5.dae" scale="${reflect} 1 1" /> -->
        <!-- <cylinder radius="0.015" length="0.07"/> -->
        <box size="0.08 0.02 0.05"/>
        <!-- TODO: set x y z size -->
      </geometry>
    </collision>
    <!-- INERTIA RF_L7  -->
    <inertial>
      <origin rpy="0 0 0" xyz="0.001048 -0.007730 -0.047829"/>
      <mass value="0.10248"/>
      <inertia ixx="0.00003528" ixy="-0.00000068" ixz="-0.00000123" iyy="0.00007729" iyz="-0.00000298" izz="0.00005640"/>
    </inertial>
   
  </link>
  <joint name="LF_J1" type="revolute">
    <parent link="body"/>
    <child link="LF_L1"/>
    <origin rpy="0 0 1.5707963267948966" xyz="0.28 0.075 0.005"/>
    <axis xyz="1 0 0"/>
    <limit effort="10.0" lower="-1.5707963267948966" upper="1.5707963267948966" velocity="10.0"/>
    <dynamics damping="0.1" friction="0.0"/>
  </joint>
  <link name="LF_L1">
    <visual>
      <origin rpy="0 0 0" xyz="0 0 0"/>
      <geometry>
        <mesh filename="package://robot_description/meshes/panda_arm/Link1.dae" scale="1 1 1"/>
      </geometry>
      <material name="red"/>
    </visual>
    <collision>
      <origin rpy="0 0 0" xyz="0.025 0.0 -0.01"/>
      <geometry>
        <cylinder length="0.085" radius="0.025"/>
      </geometry>
    </collision>
    <!-- INERTIA LF_L1 (disabled) -->
    <inertial>
      <origin rpy="0 0 0" xyz="0.024340 0.000290 -0.009336"/>
      <mass value="0.21205"/>
      <inertia ixx="0.00014885" ixy="-0.00000038" ixz="0.00000863" iyy="0.00012057" iyz="0.00000411" izz="0.00009025"/>
    </inertial>
   
  </link>
  <joint name="LF_J2" type="revolute">
    <parent link="LF_L1"/>
    <child link="LF_L2"/>
    <origin rpy="0 0 -1.5707963267948966" xyz="0.026 0.0025 -0.0375"/>
    <axis xyz="1 0 0"/>
    <limit effort="10.0" lower="-1.5707963267948966" upper="1.5707963267948966" velocity="10.0"/>
    <dynamics damping="0.1" friction="0.0"/>
  </joint>
  <link name="LF_L2">
    <visual>
      <origin rpy="0 0 0" xyz="0 0 0"/>
      <geometry>
        <mesh filename="package://robot_description/meshes/panda_arm/Link2.dae" scale="1 1 1"/>
      </geometry>
      <material name="red"/>
    </visual>
    <collision>
      <origin rpy="0 0 0" xyz="0.0 0.01 -0.055"/>
      <geometry>
        <cylinder length="0.04" radius="0.025"/>
      </geometry>
    </collision>
    <!-- INERTIA LF_L2  -->
    <inertial>
      <origin rpy="0 0 0" xyz="0.000319 0.007895 -0.042269"/>
      <mass value="0.12339"/>
      <inertia ixx="0.00007467" ixy="0.00000015" ixz="-0.00000018" iyy="0.00007863" iyz="0.00000833" izz="0.00005700"/>
    </inertial>
   
  </link>
  <joint name="LF_J3" type="revolute">
    <parent link="LF_L2"/>
    <child link="LF_L3"/>
    <origin rpy="0 1.5707963267948966 3.141592653589793" xyz="0 -0.004 -0.0555"/>
    <axis xyz="1 0 0"/>
    <limit effort="10.0" lower="-1.5707963267948966" upper="1.5707963267948966" velocity="10.0"/>
    <dynamics damping="0.1" friction="0.0"/>
  </joint>
  <link name="LF_L3">
    <visual>
      <origin rpy="0 0 0" xyz="0 0 0"/>
      <geometry>
        <mesh filename="package://robot_description/meshes/panda_arm/Link3.dae" scale="1 1 1"/>
      </geometry>
      <material name="red"/>
    </visual>
    <collision>
      <origin rpy="1.5707963267948966 0 0" xyz="0.005 0.028 0.0"/>
      <geometry>
        <cylinder length="0.01" radius="0.025"/>
      </geometry>
    </collision>
    <!-- INERTIA LF_L3  -->
    <inertial>
      <origin rpy="0 0 0" xyz="0.017019 0.023760 -0.000188"/>
      <mass value="0.02605"/>
      <inertia ixx="0.00000523" ixy="0.00000090" ixz="0.00000009" iyy="0.00013027" iyz="0.00000007" izz="0.00001104"/>
    </inertial>
   
  </link>
  <joint name="LF_J4" type="revolute">
    <parent link="LF_L3"/>
    <child link="LF_L4"/>
    <origin rpy="0 1.5707963267948966 3.141592653589793" xyz="0.058 0.0195 0.001"/>
    <axis xyz="1 0 0"/>
    <limit effort="10.0" lower="-1.5707963267948966" upper="1.5707963267948966" velocity="10.0"/>
    <dynamics damping="0.1" friction="0.0"/>
  </joint>
  <link name="LF_L4">
    <visual>
      <origin rpy="0 0 0" xyz="0 0 0"/>
      <geometry>
        <mesh filename="package://robot_description/meshes/panda_arm/Link4.dae" scale="1 -1 1"/>
      </geometry>
      <material name="red"/>
    </visual>
    <collision>
      <origin rpy="0 0 0" xyz="0.01 +0.015 -0.04"/>
      <geometry>
        <cylinder length="0.05" radius="0.03"/>
      </geometry>
    </collision>
    <!-- INERTIA LF_L4 (mirrored from RF_L4 along Y) -->
    <inertial>
      <origin rpy="0 0 0" xyz="0.005528 0.015452 -0.024028"/>
      <mass value="0.21197"/>
      <inertia ixx="0.00016760" ixy="0.00000028" ixz="0.00001932" iyy="0.00017551" iyz="0.00000051" izz="0.00008108"/>
    </inertial>
   
  </link>
  <joint name="LF_J5" type="revolute">
    <parent link="LF_L4"/>
    <child link="LF_L5"/>
    <origin rpy="1.5707963267948966 -1.5707963267948966 0" xyz="-0.0073 0.016 -0.04725"/>
    <axis xyz="1 0 0"/>
    <limit effort="10.0" lower="-1.5707963267948966" upper="1.5707963267948966" velocity="10.0"/>
    <dynamics damping="0.1" friction="0.0"/>
  </joint>
  <link name="LF_L5">
    <visual>
      <origin rpy="0 0 0" xyz="0 0 0"/>
      <geometry>
        <mesh filename="package://robot_description/meshes/panda_arm/Link5.dae" scale="1 1 1"/>
      </geometry>
      <material name="red"/>
    </visual>
    <collision>
      <origin rpy="1.5707963267948966 0 1.5707963267948966" xyz="-0.05 0.0225 0"/>
      <geometry>
        <cylinder length="0.0525" radius="0.0175"/>
      </geometry>
    </collision>
    <!-- INERTIA LF_L5  -->
    <inertial>
      <origin rpy="0 0 0" xyz="-0.039812 0.022259 -0.000292"/>
      <mass value="0.11428"/>
      <inertia ixx="0.00002245" ixy="-0.00000489" ixz="-0.00000014" iyy="0.00008311" iyz="-0.00000020" izz="0.00007996"/>
    </inertial>
   
  </link>
  <joint name="LF_J6" type="revolute">
    <parent link="LF_L5"/>
    <child link="LF_L6"/>
    <origin rpy="0 1.5707963267948966 0" xyz="-0.065 0.021 0"/>
    <axis xyz="1 0 0"/>
    <limit effort="10.0" lower="-1.5707963267948966" upper="1.5707963267948966" velocity="10.0"/>
    <dynamics damping="0.1" friction="0.0"/>
  </joint>
  <link name="LF_L6">
    <visual>
      <origin rpy="0 0 0" xyz="0 0 0"/>
      <geometry>
        <mesh filename="package://robot_description/meshes/panda_arm/Link6.dae" scale="-1 1 1"/>
      </geometry>
      <material name="red"/>
    </visual>
    <collision>
      <origin rpy="0 0 0" xyz="0.0 0.0 -0.06"/>
      <geometry>
        <box size="0.065 0.02 0.06"/>
        <!-- TODO: set x y z size -->
      </geometry>
    </collision>
    <!-- INERTIA LF_L6 (mirrored from RF_L6 along X) -->
    <inertial>
      <origin rpy="0 0 0" xyz="0.005400 0.000762 -0.054807"/>
      <mass value="0.20986"/>
      <inertia ixx="0.00011473" ixy="0.00001510" ixz="-0.00000999" iyy="0.00017398" iyz="0.00001411" izz="0.00013573"/>
    </inertial>
   
  </link>
  <joint name="LF_J7" type="revolute">
    <parent link="LF_L6"/>
    <child link="LF_L7"/>
    <origin rpy="0 0 0" xyz="0 0.007 -0.08"/>
    <axis xyz="1 0 0"/>
    <limit effort="10.0" lower="-1.5707963267948966" upper="1.5707963267948966" velocity="10.0"/>
    <dynamics damping="0.1" friction="0.0"/>
  </joint>
  <link name="LF_L7">
    <visual>
      <origin rpy="0 0 0" xyz="0 0 0"/>
      <geometry>
        <mesh filename="package://robot_description/meshes/panda_arm/Link7.dae" scale="1 1 1"/>
      </geometry>
      <!-- <material name="blue" /> -->
    </visual>
    <collision>
      <!-- <origin xyz="0 0 0" rpy="0 0 0" />
                <geometry>
                    <mesh filename="${arm_mesh_path}/Link7.dae" scale="1 1 1" />
                </geometry> -->
      <origin rpy="0 0 0" xyz="0.0 0.0 -0.05"/>
      <geometry>
        <!-- <mesh filename="${meshes_path}/Link5.dae" scale="${reflect} 1 1" /> -->
        <!-- <cylinder radius="0.015" length="0.07"/> -->
        <box size="0.08 0.02 0.05"/>
        <!-- TODO: set x y z size -->
      </geometry>
    </collision>
    <!-- INERTIA LF_L7  -->
    <inertial>
      <origin rpy="0 0 0" xyz="0.001048 -0.007730 -0.047829"/>
      <mass value="0.10248"/>
      <inertia ixx="0.00003528" ixy="-0.00000068" ixz="-0.00000123" iyy="0.00007729" iyz="-0.00000298" izz="0.00005640"/>
    </inertial>
   

  </link>
  <joint name="RB_J1" type="revolute">
    <parent link="body"/>
    <child link="RB_L1"/>
    <origin rpy="-1.5707963267948966 0 0" xyz="-0.03 -0.04 -0.05"/>
    <axis xyz="1 0 0"/>
    <limit effort="10.0" lower="-1.5707963267948966" upper="1.5707963267948966" velocity="10.0"/>
    <dynamics damping="0.1" friction="0.0"/>
  </joint>
  <link name="RB_L1">
    <visual>
      <origin rpy="0 0 0" xyz="0 0 0"/>
      <geometry>
        <mesh filename="package://robot_description/meshes/panda_leg/Link1.dae" scale="-1 1 1"/>
      </geometry>
      <material name="red"/>
    </visual>
    <collision>
      <origin rpy="0 0 0" xyz="-0.04 0.0 -0.02"/>
      <geometry>
        <cylinder length="0.075" radius="0.035"/>
      </geometry>
    </collision>
    <!-- INERTIA RB_L1 (X-flipped mesh, so CoM x negated, ixy and ixz negated) -->
    <inertial>
      <origin rpy="0 0 0" xyz="-0.028971 -0.000107 -0.018559"/>
      <mass value="0.399"/>
      <inertia ixx="0.00032351" ixy="-0.00000101" ixz="-0.00001007" iyy="0.00030113" iyz="-0.00000164" izz="0.00031142"/>
    </inertial>
   
  </link>
  <joint name="RB_J2" type="revolute">
    <parent link="RB_L1"/>
    <child link="RB_L2"/>
    <origin rpy="-3.141592653589793 1.5707963267948966 0" xyz="-0.0485 0.00 -0.06210"/>
    <axis xyz="1 0 0"/>
    <limit effort="10.0" lower="-1.5707963267948966" upper="1.5707963267948966" velocity="10.0"/>
    <dynamics damping="0.1" friction="0.0"/>
  </joint>
  <link name="RB_L2">
    <visual>
      <origin rpy="0 0 0" xyz="0 0 0"/>
      <geometry>
        <mesh filename="package://robot_description/meshes/panda_leg/Link2.dae" scale="-1 1 -1"/>
      </geometry>
      <material name="red"/>
    </visual>
    <collision>
      <origin rpy="1.5707963267948966 0 0" xyz="0.03 -0.06 -0.005"/>
      <geometry>
        <cylinder length="0.16" radius="0.0275"/>
      </geometry>
    </collision>
    <!-- INERTIA RB_L2 (mirrored from LB_L2 along X) -->
    <inertial>
      <origin rpy="0 0 0" xyz="0.028482 -0.066047 0.001028"/>
      <mass value="0.29023"/>
      <inertia ixx="0.00085932" ixy="0.00007468" ixz="0.00000037" iyy="0.00016110" iyz="-0.00000441" izz="0.00081281"/>
    </inertial>
  </link>
  <joint name="RB_J3" type="revolute">
    <parent link="RB_L2"/>
    <child link="RB_L3"/>
    <origin rpy="1.5707963267948966 3.141592653589793 0" xyz="0.033 -0.11975 0.01875"/>
    <axis xyz="1 0 0"/>
    <limit effort="10.0" lower="-1.5707963267948966" upper="1.5707963267948966" velocity="10.0"/>
    <dynamics damping="0.1" friction="0.0"/>
  </joint>
  <link name="RB_L3">
    <visual>
      <origin rpy="0 0 0" xyz="0 0 0"/>
      <geometry>
        <mesh filename="package://robot_description/meshes/panda_leg/Link3.dae" scale="1 1 1"/>
      </geometry>
      <material name="red"/>
    </visual>
    <collision>
      <origin rpy="1.5707963267948966 0 0" xyz="0.0 -0.05 0.0"/>
      <geometry>
        <cylinder length="0.055" radius="0.03"/>
      </geometry>
    </collision>
    <inertial>
      <origin rpy="0 0 0" xyz="0.000069 -0.055725 0.001186"/>
      <mass value="0.12"/>
      <inertia ixx="0.00009751" ixy="0.00000010" ixz="-0.00000012" iyy="0.00005226" iyz="0.00000224" izz="0.00012515"/>
    </inertial>
  </link>
  <joint name="RB_J4" type="revolute">
    <parent link="RB_L3"/>
    <child link="RB_L4"/>
    <origin rpy="-1.5707963267948966 0 0" xyz="0.0 -0.09075 0.0"/>
    <axis xyz="1 0 0"/>
    <limit effort="10.0" lower="-1.5707963267948966" upper="1.5707963267948966" velocity="10.0"/>
    <dynamics damping="0.1" friction="0.0"/>
  </joint>
  <link name="RB_L4">
    <visual>
      <origin rpy="0 0 0" xyz="0 0 0"/>
      <geometry>
        <mesh filename="package://robot_description/meshes/panda_leg/Link4.dae" scale="1 1 1"/>
      </geometry>
      <material name="red"/>
    </visual>
    <collision>
      <origin rpy="0 0 0" xyz="0.0 0.0 -0.06"/>
      <geometry>
        <box size="0.065 0.02 0.06"/>
        <!-- TODO: set x y z size -->
      </geometry>
    </collision>
    <inertial>
      <origin rpy="0 0 0" xyz="-0.005400 0.000762 -0.054807"/>
      <mass value="0.20986"/>
      <inertia ixx="0.00011473" ixy="-0.00001510" ixz="0.00000999" iyy="0.00017398" iyz="0.00001411" izz="0.00013573"/>
    </inertial>
  </link>
  <joint name="RB_J5" type="revolute">
    <parent link="RB_L4"/>
    <child link="RB_L5"/>
    <origin rpy="0 0 0" xyz="0 0.007 -0.08"/>
    <axis xyz="1 0 0"/>
    <limit effort="10.0" lower="-1.5707963267948966" upper="1.5707963267948966" velocity="10.0"/>
    <dynamics damping="0.1" friction="0.0"/>
  </joint>
  <link name="RB_L5">
    <visual>
      <origin rpy="0 0 0" xyz="0 0 0"/>
      <geometry>
        <mesh filename="package://robot_description/meshes/panda_leg/Link5.dae" scale="1 1 1"/>
      </geometry>
      <!-- <material name="blue" /> -->
    </visual>
    <collision>
      <origin rpy="0 0 0" xyz="0.0 0.0 -0.05"/>
      <geometry>
        <!-- <mesh filename="${meshes_path}/Link5.dae" scale="${reflect} 1 1" /> -->
        <!-- <cylinder radius="0.015" length="0.07"/> -->
        <box size="0.08 0.02 0.05"/>
        <!-- TODO: set x y z size -->
      </geometry>
    </collision>
    <inertial>
      <origin rpy="0 0 0" xyz="0.001048 -0.007730 -0.047829"/>
      <mass value="0.10248"/>
      <inertia ixx="0.00003528" ixy="-0.00000068" ixz="-0.00000123" iyy="0.00007729" iyz="-0.00000298" izz="0.00005640"/>
    </inertial>
  </link>
  <joint name="LB_J1" type="revolute">
    <parent link="body"/>
    <child link="LB_L1"/>
    <origin rpy="1.5707963267948966 0 0" xyz="-0.03 0.04 -0.05"/>
    <axis xyz="1 0 0"/>
    <limit effort="10.0" lower="-1.5707963267948966" upper="1.5707963267948966" velocity="10.0"/>
    <dynamics damping="0.1" friction="0.0"/>
  </joint>
  <link name="LB_L1">
    <visual>
      <origin rpy="0 0 0" xyz="0 0 0"/>
      <geometry>
        <mesh filename="package://robot_description/meshes/panda_leg/Link1.dae" scale="-1 1 1"/>
      </geometry>
      <material name="red"/>
    </visual>
    <collision>
      <origin rpy="0 0 0" xyz="-0.04 0.0 -0.02"/>
      <geometry>
        <cylinder length="0.075" radius="0.035"/>
      </geometry>
    </collision>
    <!-- INERTIA LB_L1 (X-flipped mesh, same as RB_L1) -->
    <inertial>
      <origin rpy="0 0 0" xyz="-0.028971 -0.000107 -0.018559"/>
      <mass value="0.399"/>
      <inertia ixx="0.00032351" ixy="-0.00000101" ixz="-0.00001007" iyy="0.00030113" iyz="-0.00000164" izz="0.00031142"/>
    </inertial>
  </link>
  <joint name="LB_J2" type="revolute">
    <parent link="LB_L1"/>
    <child link="LB_L2"/>
    <origin rpy="0 -1.5707963267948966 0" xyz="-0.0485 0.00 -0.06210"/>
    <axis xyz="1 0 0"/>
    <limit effort="10.0" lower="-1.5707963267948966" upper="1.5707963267948966" velocity="10.0"/>
    <dynamics damping="0.1" friction="0.0"/>
  </joint>
  <link name="LB_L2">
    <visual>
      <origin rpy="0 0 0" xyz="0 0 0"/>
      <geometry>
        <mesh filename="package://robot_description/meshes/panda_leg/Link2.dae" scale="1 1 -1"/>
      </geometry>
      <material name="red"/>
    </visual>
    <collision>
      <origin rpy="1.5707963267948966 0 0" xyz="-0.03 -0.060 -0.005"/>
      <geometry>
        <cylinder length="0.16" radius="0.0275"/>
      </geometry>
    </collision>
    <inertial>
      <origin rpy="0 0 0" xyz="-0.028482 -0.066047 0.001028"/>
      <mass value="0.29023"/>
      <inertia ixx="0.00085932" ixy="-0.00007468" ixz="-0.00000037" iyy="0.00016110" iyz="-0.00000441" izz="0.00081281"/>
    </inertial>
  </link>
  <joint name="LB_J3" type="revolute">
    <parent link="LB_L2"/>
    <child link="LB_L3"/>
    <origin rpy="1.5707963267948966 3.141592653589793 0" xyz="-0.033 -0.11975 0.01875"/>
    <axis xyz="1 0 0"/>
    <limit effort="10.0" lower="-1.5707963267948966" upper="1.5707963267948966" velocity="10.0"/>
    <dynamics damping="0.1" friction="0.0"/>
  </joint>
  <link name="LB_L3">
    <visual>
      <origin rpy="0 0 0" xyz="0 0 0"/>
      <geometry>
        <mesh filename="package://robot_description/meshes/panda_leg/Link3.dae" scale="1 1 1"/>
      </geometry>
      <material name="red"/>
    </visual>
    <collision>
      <origin rpy="1.5707963267948966 0 0" xyz="0.0 -0.05 0.0"/>
      <geometry>
        <cylinder length="0.055" radius="0.03"/>
      </geometry>
    </collision>
    <inertial>
      <origin rpy="0 0 0" xyz="0.000069 -0.055725 0.001186"/>
      <mass value="0.12"/>
      <inertia ixx="0.00009751" ixy="0.00000010" ixz="-0.00000012" iyy="0.00005226" iyz="0.00000224" izz="0.00012515"/>
    </inertial>
  </link>
  <joint name="LB_J4" type="revolute">
    <parent link="LB_L3"/>
    <child link="LB_L4"/>
    <origin rpy="-1.5707963267948966 0 0" xyz="0.0 -0.09075 0.0"/>
    <axis xyz="1 0 0"/>
    <limit effort="10.0" lower="-1.5707963267948966" upper="1.5707963267948966" velocity="10.0"/>
    <dynamics damping="0.1" friction="0.0"/>
  </joint>
  <link name="LB_L4">
    <visual>
      <origin rpy="0 0 0" xyz="0 0 0"/>
      <geometry>
        <mesh filename="package://robot_description/meshes/panda_leg/Link4.dae" scale="-1 1 1"/>
      </geometry>
      <material name="red"/>
    </visual>
    <collision>
      <origin rpy="0 0 0" xyz="0.0 0.0 -0.06"/>
      <geometry>
        <box size="0.065 0.02 0.06"/>
        <!-- TODO: set x y z size -->
      </geometry>
    </collision>
    <!-- INERTIA LB_L4 (mirrored from RB_L4 along X) -->
    <inertial>
      <origin rpy="0 0 0" xyz="0.005400 0.000762 -0.054807"/>
      <mass value="0.20986"/>
      <inertia ixx="0.00011473" ixy="0.00001510" ixz="-0.00000999" iyy="0.00017398" iyz="0.00001411" izz="0.00013573"/>
    </inertial>
  </link>
  <joint name="LB_J5" type="revolute">
    <parent link="LB_L4"/>
    <child link="LB_L5"/>
    <origin rpy="0 0 0" xyz="0 0.007 -0.08"/>
    <axis xyz="1 0 0"/>
    <limit effort="10.0" lower="-1.5707963267948966" upper="1.5707963267948966" velocity="10.0"/>
    <dynamics damping="0.1" friction="0.0"/>
  </joint>
  <link name="LB_L5">
    <visual>
      <origin rpy="0 0 0" xyz="0 0 0"/>
      <geometry>
        <mesh filename="package://robot_description/meshes/panda_leg/Link5.dae" scale="1 1 1"/>
      </geometry>
      <!-- <material name="blue" /> -->
    </visual>
    <collision>
      <origin rpy="0 0 0" xyz="0.0 0.0 -0.05"/>
      <geometry>
        <!-- <mesh filename="${meshes_path}/Link5.dae" scale="${reflect} 1 1" /> -->
        <!-- <cylinder radius="0.015" length="0.07"/> -->
        <box size="0.08 0.02 0.05"/>
        <!-- TODO: set x y z size -->
      </geometry>
    </collision>
    <inertial>
      <origin rpy="0 0 0" xyz="0.001048 -0.007730 -0.047829"/>
      <mass value="0.10248"/>
      <inertia ixx="0.00003528" ixy="-0.00000068" ixz="-0.00000123" iyy="0.00007729" iyz="-0.00000298" izz="0.00005640"/>
    </inertial>
  </link>
</robot>
