<?xml version="1.0" ?>
<!-- =================================================================================== -->
<!-- |    This document was autogenerated by xacro from panda.xacro                    | -->
<!-- |    EDITING THIS FILE BY HAND IS NOT RECOMMENDED                                 | -->
<!-- =================================================================================== -->
<robot name="panda">
  <!--!TEST -->
  <!-- <xacro:include filename="joints.xacro" /> 
    <xacro:include filename="constants.xacro" />
    <xacro:include filename="materials.xacro" />
    <link name="base" />
    <xacro:panda_arm_L1 prefix="RF" parent="base" xyz="0 0 0" rpy="0 0 0" /> -->
  <!--!TEST -->
  <!-- <xacro:include filename="joints.xacro" />
    <xacro:include filename="constants.xacro" />
    <xacro:include filename="materials.xacro" />
    <link name="base" />
    <xacro:panda_arm_L2 prefix="RF" parent="base" xyz="0 0 0" rpy="0 0 0" /> -->
  <!--!TEST -->
  <!-- <xacro:include filename="joints.xacro" />  
    <xacro:include filename="constants.xacro" />
    <xacro:include filename="materials.xacro" />
    <link name="base" />
    <xacro:panda_arm_L3 prefix="RF" parent="base" xyz="0 0 0" rpy="0 0 0" /> -->
  <!--!TEST -->
  <!-- <xacro:include filename="joints.xacro" />  
    <xacro:include filename="constants.xacro" />
    <xacro:include filename="materials.xacro" />
    <link name="base" />
    <xacro:panda_arm_L4 prefix="RF" parent="base" xyz="0 0 0" rpy="0 0 0" /> -->
  <!--!TEST -->
  <!-- <xacro:include filename="joints.xacro" />  
    <xacro:include filename="constants.xacro" />
    <xacro:include filename="materials.xacro" />
    <link name="base" />
    <xacro:panda_arm_L5 prefix="RF" parent="base" xyz="0 0 0" rpy="0 0 0" /> -->
  <!--!TEST -->
  <!-- <xacro:include filename="../joints.xacro" />  
    <xacro:include filename="../constants.xacro" />
    <xacro:include filename="../materials.xacro" />
    <link name="base" />
    <xacro:panda_arm_L6 prefix="RF" parent="base" xyz="0 0 0" rpy="0 0 0" /> -->
  <!--!TEST -->
  <!-- <xacro:include filename="joints.xacro" />  
    <xacro:include filename="constants.xacro" />
    <xacro:include filename="materials.xacro" />

    <link name="base" />
    <xacro:panda_arm_L7 prefix="RF" parent="base" xyz="0 0 0" rpy="0 0 0" /> -->
  <!--! TEST -->
  <!-- <xacro:include filename="../joints.xacro"/>
    <xacro:include filename="../materials.xacro"/>
    <xacro:include filename="../constants.xacro"/>
    <link name="base"/>
    <xacro:lf_arm prefix="LF" parent="base" xyz="0 0 0" rpy="0 0 ${pi}"/> -->
  <!--!TEST -->
  <!-- <xacro:include filename="joints.xacro" /> 
    <xacro:include filename="constants.xacro" />
    <xacro:include filename="materials.xacro" />
    <link name="base" />
    <xacro:panda_arm_L1 prefix="RF" parent="base" xyz="0 0 0" rpy="0 0 0" /> -->
  <!--!TEST -->
  <!-- <xacro:include filename="joints.xacro" />
    <xacro:include filename="constants.xacro" />
    <xacro:include filename="materials.xacro" />
    <link name="base" />
    <xacro:panda_arm_L2 prefix="RF" parent="base" xyz="0 0 0" rpy="0 0 0" /> -->
  <!--!TEST -->
  <!-- <xacro:include filename="joints.xacro" />  
    <xacro:include filename="constants.xacro" />
    <xacro:include filename="materials.xacro" />
    <link name="base" />
    <xacro:panda_arm_L3 prefix="RF" parent="base" xyz="0 0 0" rpy="0 0 0" /> -->
  <!--!TEST -->
  <!-- <xacro:include filename="joints.xacro" />  
    <xacro:include filename="constants.xacro" />
    <xacro:include filename="materials.xacro" />
    <link name="base" />
    <xacro:panda_arm_L4 prefix="RF" parent="base" xyz="0 0 0" rpy="0 0 0" /> -->
  <!--!TEST -->
  <!-- <xacro:include filename="joints.xacro" />  
    <xacro:include filename="constants.xacro" />
    <xacro:include filename="materials.xacro" />
    <link name="base" />
    <xacro:panda_arm_L5 prefix="RF" parent="base" xyz="0 0 0" rpy="0 0 0" /> -->
  <!--!TEST -->
  <!-- <xacro:include filename="../joints.xacro" />  
    <xacro:include filename="../constants.xacro" />
    <xacro:include filename="../materials.xacro" />
    <link name="base" />
    <xacro:panda_arm_L6 prefix="RF" parent="base" xyz="0 0 0" rpy="0 0 0" /> -->
  <!--!TEST -->
  <!-- <xacro:include filename="joints.xacro" />  
    <xacro:include filename="constants.xacro" />
    <xacro:include filename="materials.xacro" />

    <link name="base" />
    <xacro:panda_arm_L7 prefix="RF" parent="base" xyz="0 0 0" rpy="0 0 0" /> -->
  <!--! TEST -->
  <!-- <xacro:include filename="../joints.xacro"/>
    <xacro:include filename="../materials.xacro"/>
    <xacro:include filename="../constants.xacro"/> 
    <link name="base"/>
    <xacro:rf_arm prefix="RF" parent="base" xyz="0 0 0" rpy="0 0 0"/> -->
  <!--!TEST -->
  <!-- <xacro:include filename="../joints.xacro" /> 
    <xacro:include filename="../constants.xacro" />
    <xacro:include filename="../materials.xacro" />
    <link name="base" />
    <xacro:panda_leg_L1 prefix="RF" parent="base" xyz="0 0 0" rpy="0 0 0" /> -->
  <!--!TEST -->
  <!-- <xacro:include filename="../joints.xacro" /> 
    <xacro:include filename="../constants.xacro" />
    <xacro:include filename="../materials.xacro" />
    <link name="base" />
    <xacro:panda_leg_L2_rb prefix="RF" parent="base" xyz="0 0 0" rpy="0 0 0" /> -->
  <!--!TEST -->
  <!-- <xacro:include filename="../joints.xacro" /> 
    <xacro:include filename="../constants.xacro" />
    <xacro:include filename="../materials.xacro" />
    <link name="base" />
    <xacro:panda_leg_L3 prefix="RF" parent="base" xyz="0 0 0" rpy="0 0 0" /> -->
  <!--!TEST -->
  <!-- <xacro:include filename="../joints.xacro" /> 
    <xacro:include filename="../constants.xacro" />
    <xacro:include filename="../materials.xacro" />
    <link name="base" />
    <xacro:panda_leg_L4 prefix="RF" parent="base" xyz="0 0 0" rpy="0 0 0"/> -->
  <!--!TEST -->
  <!-- <xacro:include filename="../joints.xacro" />  
    <xacro:include filename="../constants.xacro" />
    <xacro:include filename="../materials.xacro" />

    <link name="base" />
    <xacro:panda_leg_L5 prefix="RF" parent="base" xyz="0 0 0" rpy="0 0 0" /> -->
  <!--! TEST -->
  <!-- <xacro:include filename="../joints.xacro"/>
    <xacro:include filename="../materials.xacro"/>
    <xacro:include filename="../constants.xacro"/>
    <link name="base"/>
    <xacro:lb_leg prefix="LB" parent="base" xyz="0 0 0" rpy="${pi/2} 0 0"/> -->
  <!--!TEST -->
  <!-- <xacro:include filename="../joints.xacro" /> 
    <xacro:include filename="../constants.xacro" />
    <xacro:include filename="../materials.xacro" />
    <link name="base" />
    <xacro:panda_leg_L1 prefix="RF" parent="base" xyz="0 0 0" rpy="0 0 0" /> -->
  <!--!TEST -->
  <!-- <xacro:include filename="../joints.xacro" /> 
    <xacro:include filename="../constants.xacro" />
    <xacro:include filename="../materials.xacro" />
    <link name="base" />
    <xacro:panda_leg_L2_rb prefix="RF" parent="base" xyz="0 0 0" rpy="0 0 0" /> -->
  <!--!TEST -->
  <!-- <xacro:include filename="../joints.xacro" /> 
    <xacro:include filename="../constants.xacro" />
    <xacro:include filename="../materials.xacro" />
    <link name="base" />
    <xacro:panda_leg_L3 prefix="RF" parent="base" xyz="0 0 0" rpy="0 0 0" /> -->
  <!--!TEST -->
  <!-- <xacro:include filename="../joints.xacro" /> 
    <xacro:include filename="../constants.xacro" />
    <xacro:include filename="../materials.xacro" />
    <link name="base" />
    <xacro:panda_leg_L4 prefix="RF" parent="base" xyz="0 0 0" rpy="0 0 0"/> -->
  <!--!TEST -->
  <!-- <xacro:include filename="../joints.xacro" />  
    <xacro:include filename="../constants.xacro" />
    <xacro:include filename="../materials.xacro" />

    <link name="base" />
    <xacro:panda_leg_L5 prefix="RF" parent="base" xyz="0 0 0" rpy="0 0 0" /> -->
  <!--! TEST -->
  <!-- <xacro:include filename="../joints.xacro"/>
    <xacro:include filename="../materials.xacro"/>
    <xacro:include filename="../constants.xacro"/>
    <link name="base"/>
    <xacro:rb_leg prefix="RB" parent="base" xyz="0 0 0" rpy="${-pi/2} 0 0"/> -->
  <!-- <xacro:property name="mesh_path" value="package://robot_description/meshes/panda_arm"/> -->
  <material name="red">
    <color rgba="1 0 0 1"/>
  </material>
  <material name="grey">
    <color rgba="0.75 0.75 0.75 1"/>
  </material>
  <material name="green">
    <color rgba="0 1 0 1"/>
  </material>
  <material name="blue">
    <color rgba="0 0 1 1"/>
  </material>
  <link name="body">
    <visual>
      <origin rpy="0 0 0" xyz="0 0 0"/>
      <geometry>
        <box size="0.2 0.4 0.025"/>
      </geometry>
      <material name="red"/>
    </visual>
    <collision>
      <origin rpy="0 0 0" xyz="0 0 0"/>
      <geometry>
        <box size="0.2 0.4 0.025"/>
      </geometry>
    </collision>
  </link>
  <joint name="RF_J1" type="revolute">
    <parent link="body"/>
    <child link="RF_L1"/>
    <origin rpy="0 0 0" xyz="0.1 0.15 0"/>
    <axis xyz="1 0 0"/>
    <limit effort="10.0" lower="-1.5707963267948966" upper="1.5707963267948966" velocity="10.0"/>
    <dynamics damping="0.1" friction="0.0"/>
  </joint>
  <link name="RF_L1">
    <visual>
      <origin rpy="0 0 0" xyz="0 0 0"/>
      <geometry>
        <mesh filename="/home/q200/workspace/src/robot_description/meshes/panda_arm/Link1.dae" scale="1 1 1"/>
      </geometry>
      <material name="red"/>
    </visual>
    <collision>
      <origin rpy="0 0 0" xyz="0.025 0.0 -0.01"/>
      <geometry>
        <cylinder length="0.085" radius="0.025"/>
      </geometry>
    </collision>
  </link>
  <joint name="RF_J2" type="revolute">
    <parent link="RF_L1"/>
    <child link="RF_L2"/>
    <origin rpy="0 0 -1.5707963267948966" xyz="0.026 0.0025 -0.0375"/>
    <axis xyz="1 0 0"/>
    <limit effort="10.0" lower="-1.5707963267948966" upper="1.5707963267948966" velocity="10.0"/>
    <dynamics damping="0.1" friction="0.0"/>
  </joint>
  <link name="RF_L2">
    <visual>
      <origin rpy="0 0 0" xyz="0 0 0"/>
      <geometry>
        <mesh filename="/home/q200/workspace/src/robot_description/meshes/panda_arm/Link2.dae" scale="1 1 1"/>
      </geometry>
      <material name="red"/>
    </visual>
    <collision>
      <origin rpy="0 0 0" xyz="0.0 0.01 -0.055"/>
      <geometry>
        <cylinder length="0.04" radius="0.025"/>
      </geometry>
    </collision>
  </link>
  <joint name="RF_J3" type="revolute">
    <parent link="RF_L2"/>
    <child link="RF_L3"/>
    <origin rpy="0 1.5707963267948966 3.141592653589793" xyz="0 -0.004 -0.0555"/>
    <axis xyz="1 0 0"/>
    <limit effort="10.0" lower="-1.5707963267948966" upper="1.5707963267948966" velocity="10.0"/>
    <dynamics damping="0.1" friction="0.0"/>
  </joint>
  <link name="RF_L3">
    <visual>
      <origin rpy="0 0 0" xyz="0 0 0"/>
      <geometry>
        <mesh filename="/home/q200/workspace/src/robot_description/meshes/panda_arm/Link3.dae" scale="1 1 1"/>
      </geometry>
      <material name="red"/>
    </visual>
    <collision>
      <origin rpy="1.5707963267948966 0 0" xyz="0.005 0.028 0.0"/>
      <geometry>
        <cylinder length="0.01" radius="0.025"/>
      </geometry>
    </collision>
  </link>
  <joint name="RF_J4" type="revolute">
    <parent link="RF_L3"/>
    <child link="RF_L4"/>
    <origin rpy="1.5707963267948966 -1.5707963267948966 0" xyz="0.058 0.0195 0.001"/>
    <axis xyz="1 0 0"/>
    <limit effort="10.0" lower="-1.5707963267948966" upper="1.5707963267948966" velocity="10.0"/>
    <dynamics damping="0.1" friction="0.0"/>
  </joint>
  <link name="RF_L4">
    <visual>
      <origin rpy="0 0 0" xyz="0 0 0"/>
      <geometry>
        <mesh filename="/home/q200/workspace/src/robot_description/meshes/panda_arm/Link4.dae" scale="1 1 1"/>
      </geometry>
      <material name="red"/>
    </visual>
    <collision>
      <origin rpy="0 0 0" xyz="0.01 -0.015 -0.04"/>
      <geometry>
        <cylinder length="0.05" radius="0.03"/>
      </geometry>
    </collision>
  </link>
  <joint name="RF_J5" type="revolute">
    <parent link="RF_L4"/>
    <child link="RF_L5"/>
    <origin rpy="1.5707963267948966 -1.5707963267948966 0" xyz="-0.0073 -0.016 -0.04725"/>
    <axis xyz="1 0 0"/>
    <limit effort="10.0" lower="-1.5707963267948966" upper="1.5707963267948966" velocity="10.0"/>
    <dynamics damping="0.1" friction="0.0"/>
  </joint>
  <link name="RF_L5">
    <visual>
      <origin rpy="0 0 0" xyz="0 0 0"/>
      <geometry>
        <mesh filename="/home/q200/workspace/src/robot_description/meshes/panda_arm/Link5.dae" scale="1 1 1"/>
      </geometry>
      <material name="red"/>
    </visual>
    <collision>
      <origin rpy="1.5707963267948966 0 1.5707963267948966" xyz="-0.05 0.0225 0"/>
      <geometry>
        <cylinder length="0.0525" radius="0.0175"/>
      </geometry>
    </collision>
  </link>
  <joint name="RF_J6" type="revolute">
    <parent link="RF_L5"/>
    <child link="RF_L6"/>
    <origin rpy="0 1.5707963267948966 0" xyz="-0.065 0.021 0"/>
    <axis xyz="1 0 0"/>
    <limit effort="10.0" lower="-1.5707963267948966" upper="1.5707963267948966" velocity="10.0"/>
    <dynamics damping="0.1" friction="0.0"/>
  </joint>
  <link name="RF_L6">
    <visual>
      <origin rpy="0 0 0" xyz="0 0 0"/>
      <geometry>
        <mesh filename="/home/q200/workspace/src/robot_description/meshes/panda_arm/Link6.dae" scale="1 1 1"/>
      </geometry>
      <material name="red"/>
    </visual>
    <collision>
      <origin rpy="0 0 0" xyz="0.0 0.0 -0.025"/>
      <geometry>
        <cylinder length="0.005" radius="0.02"/>
      </geometry>
    </collision>
  </link>
  <joint name="RF_J7" type="fixed">
    <origin rpy="0 0 0" xyz="0 0 -0.031"/>
    <parent link="RF_L6"/>
    <child link="RF_L7"/>
  </joint>
  <link name="RF_L7">
    <visual>
      <origin rpy="0 0 0" xyz="0 0 0"/>
      <geometry>
        <cylinder length="0.005" radius="0.01"/>
      </geometry>
      <material name="blue"/>
    </visual>
    <collision>
      <origin rpy="0 0 0" xyz="0 0 0"/>
      <geometry>
        <cylinder length="0.005" radius="0.01"/>
      </geometry>
    </collision>
  </link>
  <joint name="LF_J1" type="revolute">
    <parent link="body"/>
    <child link="LF_L1"/>
    <origin rpy="0 0 3.141592653589793" xyz="-0.1 0.15 0"/>
    <axis xyz="1 0 0"/>
    <limit effort="10.0" lower="-1.5707963267948966" upper="1.5707963267948966" velocity="10.0"/>
    <dynamics damping="0.1" friction="0.0"/>
  </joint>
  <link name="LF_L1">
    <visual>
      <origin rpy="0 0 0" xyz="0 0 0"/>
      <geometry>
        <mesh filename="/home/q200/workspace/src/robot_description/meshes/panda_arm/Link1.dae" scale="1 1 1"/>
      </geometry>
      <material name="red"/>
    </visual>
    <collision>
      <origin rpy="0 0 0" xyz="0.025 0.0 -0.01"/>
      <geometry>
        <cylinder length="0.085" radius="0.025"/>
      </geometry>
    </collision>
  </link>
  <joint name="LF_J2" type="revolute">
    <parent link="LF_L1"/>
    <child link="LF_L2"/>
    <origin rpy="0 0 -1.5707963267948966" xyz="0.026 0.0025 -0.0375"/>
    <axis xyz="1 0 0"/>
    <limit effort="10.0" lower="-1.5707963267948966" upper="1.5707963267948966" velocity="10.0"/>
    <dynamics damping="0.1" friction="0.0"/>
  </joint>
  <link name="LF_L2">
    <visual>
      <origin rpy="0 0 0" xyz="0 0 0"/>
      <geometry>
        <mesh filename="/home/q200/workspace/src/robot_description/meshes/panda_arm/Link2.dae" scale="1 1 1"/>
      </geometry>
      <material name="red"/>
    </visual>
    <collision>
      <origin rpy="0 0 0" xyz="0.0 0.01 -0.055"/>
      <geometry>
        <cylinder length="0.04" radius="0.025"/>
      </geometry>
    </collision>
  </link>
  <joint name="LF_J3" type="revolute">
    <parent link="LF_L2"/>
    <child link="LF_L3"/>
    <origin rpy="0 1.5707963267948966 3.141592653589793" xyz="0 -0.004 -0.0555"/>
    <axis xyz="1 0 0"/>
    <limit effort="10.0" lower="-1.5707963267948966" upper="1.5707963267948966" velocity="10.0"/>
    <dynamics damping="0.1" friction="0.0"/>
  </joint>
  <link name="LF_L3">
    <visual>
      <origin rpy="0 0 0" xyz="0 0 0"/>
      <geometry>
        <mesh filename="/home/q200/workspace/src/robot_description/meshes/panda_arm/Link3.dae" scale="1 1 1"/>
      </geometry>
      <material name="red"/>
    </visual>
    <collision>
      <origin rpy="1.5707963267948966 0 0" xyz="0.005 0.028 0.0"/>
      <geometry>
        <cylinder length="0.01" radius="0.025"/>
      </geometry>
    </collision>
  </link>
  <joint name="LF_J4" type="revolute">
    <parent link="LF_L3"/>
    <child link="LF_L4"/>
    <origin rpy="-1.5707963267948966 1.5707963267948966 3.141592653589793" xyz="0.058 0.0195 0.001"/>
    <axis xyz="1 0 0"/>
    <limit effort="10.0" lower="-1.5707963267948966" upper="1.5707963267948966" velocity="10.0"/>
    <dynamics damping="0.1" friction="0.0"/>
  </joint>
  <link name="LF_L4">
    <visual>
      <origin rpy="0 0 0" xyz="0 0 0"/>
      <geometry>
        <mesh filename="/home/q200/workspace/src/robot_description/meshes/panda_arm/Link4.dae" scale="1 -1 1"/>
      </geometry>
      <material name="red"/>
    </visual>
    <collision>
      <origin rpy="0 0 0" xyz="0.01 +0.015 -0.04"/>
      <geometry>
        <cylinder length="0.05" radius="0.03"/>
      </geometry>
    </collision>
  </link>
  <joint name="LF_J5" type="revolute">
    <parent link="LF_L4"/>
    <child link="LF_L5"/>
    <origin rpy="1.5707963267948966 -1.5707963267948966 0" xyz="-0.0073 0.016 -0.04725"/>
    <axis xyz="1 0 0"/>
    <limit effort="10.0" lower="-1.5707963267948966" upper="1.5707963267948966" velocity="10.0"/>
    <dynamics damping="0.1" friction="0.0"/>
  </joint>
  <link name="LF_L5">
    <visual>
      <origin rpy="0 0 0" xyz="0 0 0"/>
      <geometry>
        <mesh filename="/home/q200/workspace/src/robot_description/meshes/panda_arm/Link5.dae" scale="1 1 1"/>
      </geometry>
      <material name="red"/>
    </visual>
    <collision>
      <origin rpy="1.5707963267948966 0 1.5707963267948966" xyz="-0.05 0.0225 0"/>
      <geometry>
        <cylinder length="0.0525" radius="0.0175"/>
      </geometry>
    </collision>
  </link>
  <joint name="LF_J6" type="revolute">
    <parent link="LF_L5"/>
    <child link="LF_L6"/>
    <origin rpy="0 1.5707963267948966 0" xyz="-0.065 0.021 0"/>
    <axis xyz="1 0 0"/>
    <limit effort="10.0" lower="-1.5707963267948966" upper="1.5707963267948966" velocity="10.0"/>
    <dynamics damping="0.1" friction="0.0"/>
  </joint>
  <link name="LF_L6">
    <visual>
      <origin rpy="0 0 0" xyz="0 0 0"/>
      <geometry>
        <mesh filename="/home/q200/workspace/src/robot_description/meshes/panda_arm/Link6.dae" scale="1 1 1"/>
      </geometry>
      <material name="red"/>
    </visual>
    <collision>
      <origin rpy="0 0 0" xyz="0.0 0.0 -0.025"/>
      <geometry>
        <cylinder length="0.005" radius="0.02"/>
      </geometry>
    </collision>
  </link>
  <joint name="LF_J7" type="fixed">
    <origin rpy="0 0 0" xyz="0 0 -0.031"/>
    <parent link="LF_L6"/>
    <child link="LF_L7"/>
  </joint>
  <link name="LF_L7">
    <visual>
      <origin rpy="0 0 0" xyz="0 0 0"/>
      <geometry>
        <cylinder length="0.005" radius="0.01"/>
      </geometry>
      <material name="blue"/>
    </visual>
    <collision>
      <origin rpy="0 0 0" xyz="0 0 0"/>
      <geometry>
        <cylinder length="0.005" radius="0.01"/>
      </geometry>
    </collision>
  </link>
  <joint name="RB_J1" type="revolute">
    <parent link="body"/>
    <child link="RB_L1"/>
    <origin rpy="-1.5707963267948966 0 1.5707963267948966" xyz="0.02500000000000001 -0.2 0"/>
    <axis xyz="1 0 0"/>
    <limit effort="10.0" lower="-1.5707963267948966" upper="1.5707963267948966" velocity="10.0"/>
    <dynamics damping="0.1" friction="0.0"/>
  </joint>
  <link name="RB_L1">
    <visual>
      <origin rpy="0 0 0" xyz="0 0 0"/>
      <geometry>
        <mesh filename="/home/q200/workspace/src/robot_description/meshes/panda_leg/Link1.dae" scale="-1 1 1"/>
      </geometry>
      <material name="red"/>
    </visual>
    <collision>
      <origin rpy="0 0 0" xyz="-0.04 0.0 -0.01"/>
      <geometry>
        <cylinder length="0.05" radius="0.035"/>
      </geometry>
    </collision>
  </link>
  <joint name="RB_J2" type="revolute">
    <parent link="RB_L1"/>
    <child link="RB_L2"/>
    <origin rpy="-3.141592653589793 1.5707963267948966 0" xyz="-0.0485 0.00 -0.06210"/>
    <axis xyz="1 0 0"/>
    <limit effort="10.0" lower="-1.5707963267948966" upper="1.5707963267948966" velocity="10.0"/>
    <dynamics damping="0.1" friction="0.0"/>
  </joint>
  <link name="RB_L2">
    <visual>
      <origin rpy="0 0 0" xyz="0 0 0"/>
      <geometry>
        <mesh filename="/home/q200/workspace/src/robot_description/meshes/panda_leg/Link2.dae" scale="-1 1 1"/>
      </geometry>
      <material name="red"/>
    </visual>
    <collision>
      <origin rpy="1.5707963267948966 0 0" xyz="0.03 -0.06 0.005"/>
      <geometry>
        <cylinder length="0.16" radius="0.0275"/>
      </geometry>
    </collision>
  </link>
  <joint name="RB_J3" type="revolute">
    <parent link="RB_L2"/>
    <child link="RB_L3"/>
    <origin rpy="-1.5707963267948966 3.141592653589793 0" xyz="0.033 -0.11975 -0.01875"/>
    <axis xyz="1 0 0"/>
    <limit effort="10.0" lower="-1.5707963267948966" upper="1.5707963267948966" velocity="10.0"/>
    <dynamics damping="0.1" friction="0.0"/>
  </joint>
  <link name="RB_L3">
    <visual>
      <origin rpy="0 0 0" xyz="0 0 0"/>
      <geometry>
        <mesh filename="/home/q200/workspace/src/robot_description/meshes/panda_leg/Link3.dae" scale="1 1 1"/>
      </geometry>
      <material name="red"/>
    </visual>
    <collision>
      <origin rpy="1.5707963267948966 0 0" xyz="0.0 -0.05 0.0"/>
      <geometry>
        <cylinder length="0.055" radius="0.03"/>
      </geometry>
    </collision>
  </link>
  <joint name="RB_J4" type="revolute">
    <parent link="RB_L3"/>
    <child link="RB_L4"/>
    <origin rpy="-1.5707963267948966 0 0" xyz="0.0 -0.09075 0.0"/>
    <axis xyz="1 0 0"/>
    <limit effort="10.0" lower="-1.5707963267948966" upper="1.5707963267948966" velocity="10.0"/>
    <dynamics damping="0.1" friction="0.0"/>
  </joint>
  <link name="RB_L4">
    <visual>
      <origin rpy="0 0 0" xyz="0 0 0"/>
      <geometry>
        <mesh filename="/home/q200/workspace/src/robot_description/meshes/panda_leg/Link4.dae" scale="1 1 1"/>
      </geometry>
      <material name="red"/>
    </visual>
    <collision>
      <origin rpy="0 0 0" xyz="0.0 0.0 -0.025"/>
      <geometry>
        <cylinder length="0.005" radius="0.02"/>
      </geometry>
    </collision>
  </link>
  <joint name="RB_J5" type="fixed">
    <origin rpy="0 0 0" xyz="0 0 -0.031"/>
    <parent link="RB_L4"/>
    <child link="RB_L5"/>
  </joint>
  <link name="RB_L5">
    <visual>
      <origin rpy="0 0 0" xyz="0 0 0"/>
      <geometry>
        <cylinder length="0.005" radius="0.01"/>
      </geometry>
      <material name="blue"/>
    </visual>
    <collision>
      <origin rpy="0 0 0" xyz="0 0 0"/>
      <geometry>
        <cylinder length="0.005" radius="0.01"/>
      </geometry>
    </collision>
  </link>
  <joint name="LB_J1" type="revolute">
    <parent link="body"/>
    <child link="LB_L1"/>
    <origin rpy="1.5707963267948966 0 1.5707963267948966" xyz="-0.02500000000000001 -0.2 0"/>
    <axis xyz="1 0 0"/>
    <limit effort="10.0" lower="-1.5707963267948966" upper="1.5707963267948966" velocity="10.0"/>
    <dynamics damping="0.1" friction="0.0"/>
  </joint>
  <link name="LB_L1">
    <visual>
      <origin rpy="0 0 0" xyz="0 0 0"/>
      <geometry>
        <mesh filename="/home/q200/workspace/src/robot_description/meshes/panda_leg/Link1.dae" scale="-1 1 1"/>
      </geometry>
      <material name="red"/>
    </visual>
    <collision>
      <origin rpy="0 0 0" xyz="-0.04 0.0 -0.01"/>
      <geometry>
        <cylinder length="0.05" radius="0.035"/>
      </geometry>
    </collision>
  </link>
  <joint name="LB_J2" type="revolute">
    <parent link="LB_L1"/>
    <child link="LB_L2"/>
    <origin rpy="0 -1.5707963267948966 0" xyz="-0.0485 0.00 -0.06210"/>
    <axis xyz="1 0 0"/>
    <limit effort="10.0" lower="-1.5707963267948966" upper="1.5707963267948966" velocity="10.0"/>
    <dynamics damping="0.1" friction="0.0"/>
  </joint>
  <link name="LB_L2">
    <visual>
      <origin rpy="0 0 0" xyz="0 0 0"/>
      <geometry>
        <mesh filename="/home/q200/workspace/src/robot_description/meshes/panda_leg/Link2.dae" scale="1 1 1"/>
      </geometry>
      <material name="red"/>
    </visual>
    <collision>
      <origin rpy="1.5707963267948966 0 0" xyz="-0.03 -0.06 0.005"/>
      <geometry>
        <cylinder length="0.16" radius="0.0275"/>
      </geometry>
    </collision>
  </link>
  <joint name="LB_J3" type="revolute">
    <parent link="LB_L2"/>
    <child link="LB_L3"/>
    <origin rpy="-1.5707963267948966 3.141592653589793 0" xyz="-0.033 -0.11975 -0.01875"/>
    <axis xyz="1 0 0"/>
    <limit effort="10.0" lower="-1.5707963267948966" upper="1.5707963267948966" velocity="10.0"/>
    <dynamics damping="0.1" friction="0.0"/>
  </joint>
  <link name="LB_L3">
    <visual>
      <origin rpy="0 0 0" xyz="0 0 0"/>
      <geometry>
        <mesh filename="/home/q200/workspace/src/robot_description/meshes/panda_leg/Link3.dae" scale="1 1 1"/>
      </geometry>
      <material name="red"/>
    </visual>
    <collision>
      <origin rpy="1.5707963267948966 0 0" xyz="0.0 -0.05 0.0"/>
      <geometry>
        <cylinder length="0.055" radius="0.03"/>
      </geometry>
    </collision>
  </link>
  <joint name="LB_J4" type="revolute">
    <parent link="LB_L3"/>
    <child link="LB_L4"/>
    <origin rpy="-1.5707963267948966 0 0" xyz="0.0 -0.09075 0.0"/>
    <axis xyz="1 0 0"/>
    <limit effort="10.0" lower="-1.5707963267948966" upper="1.5707963267948966" velocity="10.0"/>
    <dynamics damping="0.1" friction="0.0"/>
  </joint>
  <link name="LB_L4">
    <visual>
      <origin rpy="0 0 0" xyz="0 0 0"/>
      <geometry>
        <mesh filename="/home/q200/workspace/src/robot_description/meshes/panda_leg/Link4.dae" scale="1 1 1"/>
      </geometry>
      <material name="red"/>
    </visual>
    <collision>
      <origin rpy="0 0 0" xyz="0.0 0.0 -0.025"/>
      <geometry>
        <cylinder length="0.005" radius="0.02"/>
      </geometry>
    </collision>
  </link>
  <joint name="LB_J5" type="fixed">
    <origin rpy="0 0 0" xyz="0 0 -0.031"/>
    <parent link="LB_L4"/>
    <child link="LB_L5"/>
  </joint>
  <link name="LB_L5">
    <visual>
      <origin rpy="0 0 0" xyz="0 0 0"/>
      <geometry>
        <cylinder length="0.005" radius="0.01"/>
      </geometry>
      <material name="blue"/>
    </visual>
    <collision>
      <origin rpy="0 0 0" xyz="0 0 0"/>
      <geometry>
        <cylinder length="0.005" radius="0.01"/>
      </geometry>
    </collision>
  </link>
</robot>
